2024-03-14 22:24:16 ERROR Traceback (most recent call last):
  File "C:\Users\Hp\.conda\envs\keras_env\lib\site-packages\wandb\cli\cli.py", line 105, in wrapper
    return func(*args, **kwargs)
  File "C:\Users\Hp\.conda\envs\keras_env\lib\site-packages\wandb\cli\cli.py", line 249, in login
    wandb.login(
  File "C:\Users\Hp\.conda\envs\keras_env\lib\site-packages\wandb\sdk\wandb_login.py", line 85, in login
    configured = _login(**kwargs)
  File "C:\Users\Hp\.conda\envs\keras_env\lib\site-packages\wandb\sdk\wandb_login.py", line 317, in _login
    wlogin.prompt_api_key()
  File "C:\Users\Hp\.conda\envs\keras_env\lib\site-packages\wandb\sdk\wandb_login.py", line 247, in prompt_api_key
    raise UsageError("api_key not configured (no-tty). call " + directive)
wandb.errors.UsageError: api_key not configured (no-tty). call wandb login [your_api_key]

